<?xml version="1.0"?>

<robot name="macros" xmlns:xacro="http://www.ros.org/wiki/xacro">

  <!--All units in m-kg-s-radians unit system -->
  <xacro:property name="M_PI" value="3.1415926535897931" />
  <xacro:property name="footprint_vertical_offset" value="-0.05" />

  <!-- Chassis -->
  <xacro:property name="chassis_height" value="0.1" />
  <xacro:property name="chassis_width" value="0.5" />
  <xacro:property name="chassis_length" value="0.6" />
  <xacro:property name="chassis_mass" value="5" /> <!-- in kg-->

  <!-- Wheels -->
  <xacro:property name="wheel_horizontal_separation" value="0.15" />
  <xacro:property name="wheel_vertical_separation" value="0.23" />
  <xacro:property name="wheel_vertical_offset" value="-0.13" />
  <xacro:property name="wheel_radius" value="0.098" />
  <xacro:property name="wheel_width" value="0.040" />

  <xacro:macro name="wheel" params="prefix trans_x trans_y trans_z">
    <link name="${prefix}_wheel">
      <visual>
        <origin xyz="0 0 0" rpy="${M_PI/2} 0 0"/>
        <geometry>
          <cylinder radius="${wheel_radius}" length="${wheel_width}"/>
        </geometry>
        <material name="Red" />
      </visual>
      <collision>
        <origin xyz="0 0 0" rpy="${M_PI/2} 0 0"/>
        <geometry>
          <cylinder radius="${wheel_radius}" length="${wheel_width}"/>
        </geometry>
      </collision>
      <inertial>
        <origin xyz="0 0 0" rpy="0 0 0"/>
        <mass value="0.477"/>
        <inertia
          ixx="0.0013" ixy="0" ixz="0"
          iyy="0.0024" iyz="0"
          izz="0.0013"/>
        </inertial>
    </link>

    <gazebo reference="${prefix}_wheel">
      <material>Gazebo/DarkGrey</material>
    </gazebo>

    <joint name="${prefix}_joint" type="continuous">
      <parent link="chassis_link"/>
      <child link="${prefix}_wheel" />
      <origin xyz="${trans_x} ${trans_y} ${trans_z}" rpy="0 0 0" />
      <axis xyz="0 1 0" />
    </joint>
  </xacro:macro>

  <xacro:macro name="cylinder_inertia" params="mass r l">
    <inertia  ixx="${mass*(3*r*r+l*l)/12}" ixy = "0" ixz = "0"
              iyy="${mass*(3*r*r+l*l)/12}" iyz = "0"
              izz="${mass*(r*r)/2}" />
  </xacro:macro>

</robot>